2023-03-24 13:44:57,951 ERROR Internal Server Error: /posts/category/2/ C:\PWS_practice\D2\NewsPaper_Django\venv\lib\site-packages\django\utils\log.py (<class 'AttributeError'>, AttributeError("'AnonymousUser' object has no attribute 'email'"), <traceback object at 0x000001BDDEC46800>)
Traceback (most recent call last):
  File "C:\PWS_practice\D2\NewsPaper_Django\venv\lib\site-packages\django\core\handlers\exception.py", line 56, in inner
    response = get_response(request)
  File "C:\PWS_practice\D2\NewsPaper_Django\venv\lib\site-packages\django\core\handlers\base.py", line 197, in _get_response
    response = wrapped_callback(request, *callback_args, **callback_kwargs)
  File "C:\PWS_practice\D2\NewsPaper_Django\venv\lib\site-packages\django\views\generic\base.py", line 103, in view
    return self.dispatch(request, *args, **kwargs)
  File "C:\PWS_practice\D2\NewsPaper_Django\venv\lib\site-packages\django\views\generic\base.py", line 142, in dispatch
    return handler(request, *args, **kwargs)
  File "C:\PWS_practice\D2\NewsPaper_Django\venv\lib\site-packages\django\views\generic\list.py", line 174, in get
    context = self.get_context_data()
  File "C:\PWS_practice\D2\NewsPaper_Django\NewsPaper\news\views.py", line 250, in get_context_data
    subscribed = categry.subscribers.filter(email=user.email)
  File "C:\PWS_practice\D2\NewsPaper_Django\venv\lib\site-packages\django\utils\functional.py", line 268, in inner
    return func(_wrapped, *args)
AttributeError: 'AnonymousUser' object has no attribute 'email'
2023-03-24 13:44:57,955 ERROR "GET /posts/category/2/ HTTP/1.1" 500 95183 C:\PWS_practice\D2\NewsPaper_Django\venv\lib\site-packages\django\core\servers\basehttp.py None
2023-03-24 13:48:37,663 ERROR Internal Server Error: /posts/category/2/ C:\PWS_practice\D2\NewsPaper_Django\venv\lib\site-packages\django\utils\log.py (<class 'AttributeError'>, AttributeError("'AnonymousUser' object has no attribute 'email'"), <traceback object at 0x00000284A31E0700>)
Traceback (most recent call last):
  File "C:\PWS_practice\D2\NewsPaper_Django\venv\lib\site-packages\django\core\handlers\exception.py", line 56, in inner
    response = get_response(request)
  File "C:\PWS_practice\D2\NewsPaper_Django\venv\lib\site-packages\django\core\handlers\base.py", line 197, in _get_response
    response = wrapped_callback(request, *callback_args, **callback_kwargs)
  File "C:\PWS_practice\D2\NewsPaper_Django\venv\lib\site-packages\django\views\generic\base.py", line 103, in view
    return self.dispatch(request, *args, **kwargs)
  File "C:\PWS_practice\D2\NewsPaper_Django\venv\lib\site-packages\django\views\generic\base.py", line 142, in dispatch
    return handler(request, *args, **kwargs)
  File "C:\PWS_practice\D2\NewsPaper_Django\venv\lib\site-packages\django\views\generic\list.py", line 174, in get
    context = self.get_context_data()
  File "C:\PWS_practice\D2\NewsPaper_Django\NewsPaper\news\views.py", line 250, in get_context_data
    subscribed = categry.subscribers.filter(email=user.email)
  File "C:\PWS_practice\D2\NewsPaper_Django\venv\lib\site-packages\django\utils\functional.py", line 268, in inner
    return func(_wrapped, *args)
AttributeError: 'AnonymousUser' object has no attribute 'email'
2023-03-24 13:48:37,667 ERROR "GET /posts/category/2/ HTTP/1.1" 500 95183 C:\PWS_practice\D2\NewsPaper_Django\venv\lib\site-packages\django\core\servers\basehttp.py None
